[2024-04-20 09:07:29,045] {taskinstance.py:1179} INFO - Dependencies all met for <TaskInstance: ETL_toll_data.extract_data_from_tsv manual__2024-04-20T09:07:25.152127+00:00 [queued]>
[2024-04-20 09:07:29,061] {taskinstance.py:1179} INFO - Dependencies all met for <TaskInstance: ETL_toll_data.extract_data_from_tsv manual__2024-04-20T09:07:25.152127+00:00 [queued]>
[2024-04-20 09:07:29,061] {taskinstance.py:1376} INFO - 
--------------------------------------------------------------------------------
[2024-04-20 09:07:29,061] {taskinstance.py:1377} INFO - Starting attempt 1 of 2
[2024-04-20 09:07:29,061] {taskinstance.py:1378} INFO - 
--------------------------------------------------------------------------------
[2024-04-20 09:07:29,078] {taskinstance.py:1397} INFO - Executing <Task(BashOperator): extract_data_from_tsv> on 2024-04-20 09:07:25.152127+00:00
[2024-04-20 09:07:29,088] {standard_task_runner.py:52} INFO - Started process 6951 to run task
[2024-04-20 09:07:29,094] {standard_task_runner.py:79} INFO - Running: ['***', 'tasks', 'run', 'ETL_toll_data', 'extract_data_from_tsv', 'manual__2024-04-20T09:07:25.152127+00:00', '--job-id', '15', '--raw', '--subdir', 'DAGS_FOLDER/ETL_toll_data.py', '--cfg-path', '/tmp/tmp0t1mycp3', '--error-file', '/tmp/tmpe9l1zbvt']
[2024-04-20 09:07:29,094] {standard_task_runner.py:80} INFO - Job 15: Subtask extract_data_from_tsv
[2024-04-20 09:07:29,209] {task_command.py:371} INFO - Running <TaskInstance: ETL_toll_data.extract_data_from_tsv manual__2024-04-20T09:07:25.152127+00:00 [running]> on host f3257ad4c610
[2024-04-20 09:07:29,352] {taskinstance.py:1591} INFO - Exporting the following env vars:
AIRFLOW_CTX_DAG_EMAIL=longdvnl@gmail.com
AIRFLOW_CTX_DAG_OWNER=Longdvnl
AIRFLOW_CTX_DAG_ID=ETL_toll_data
AIRFLOW_CTX_TASK_ID=extract_data_from_tsv
AIRFLOW_CTX_EXECUTION_DATE=2024-04-20T09:07:25.152127+00:00
AIRFLOW_CTX_TRY_NUMBER=1
AIRFLOW_CTX_DAG_RUN_ID=manual__2024-04-20T09:07:25.152127+00:00
[2024-04-20 09:07:29,354] {subprocess.py:62} INFO - Tmp dir root location: 
 /tmp
[2024-04-20 09:07:29,355] {subprocess.py:74} INFO - Running command: ['bash', '-c', 'cut -d -f5-7 /home/project/***/dags/finalassignment/._tollplaza-data.tsv >         /home/project/***/dags/finalassignment/tsv_data.csv']
[2024-04-20 09:07:29,388] {subprocess.py:85} INFO - Output:
[2024-04-20 09:07:29,416] {subprocess.py:92} INFO - cut: the delimiter must be a single character
[2024-04-20 09:07:29,416] {subprocess.py:92} INFO - Try 'cut --help' for more information.
[2024-04-20 09:07:29,417] {subprocess.py:96} INFO - Command exited with return code 1
[2024-04-20 09:07:29,451] {taskinstance.py:1909} ERROR - Task failed with exception
Traceback (most recent call last):
  File "/home/airflow/.local/lib/python3.7/site-packages/airflow/operators/bash.py", line 195, in execute
    f'Bash command failed. The command returned a non-zero exit code {result.exit_code}.'
airflow.exceptions.AirflowException: Bash command failed. The command returned a non-zero exit code 1.
[2024-04-20 09:07:29,457] {taskinstance.py:1420} INFO - Marking task as UP_FOR_RETRY. dag_id=ETL_toll_data, task_id=extract_data_from_tsv, execution_date=20240420T090725, start_date=20240420T090729, end_date=20240420T090729
[2024-04-20 09:07:29,495] {warnings.py:110} WARNING - /home/***/.local/lib/python3.7/site-packages/***/utils/email.py:119: PendingDeprecationWarning: Fetching SMTP credentials from configuration variables will be deprecated in a future release. Please set credentials using a connection instead.
  send_mime_email(e_from=mail_from, e_to=recipients, mime_msg=msg, conn_id=conn_id, dryrun=dryrun)

[2024-04-20 09:07:29,495] {configuration.py:552} WARNING - section/key [smtp/smtp_user] not found in config
[2024-04-20 09:07:29,495] {email.py:228} INFO - Email alerting: attempt 1
[2024-04-20 09:07:29,509] {configuration.py:552} WARNING - section/key [smtp/smtp_user] not found in config
[2024-04-20 09:07:29,509] {email.py:228} INFO - Email alerting: attempt 1
[2024-04-20 09:07:29,510] {taskinstance.py:1964} ERROR - Failed to send email to: ['longdvnl@gmail.com']
Traceback (most recent call last):
  File "/home/airflow/.local/lib/python3.7/site-packages/airflow/models/taskinstance.py", line 1471, in _run_raw_task
    self._execute_task_with_callbacks(context, test_mode)
  File "/home/airflow/.local/lib/python3.7/site-packages/airflow/models/taskinstance.py", line 1618, in _execute_task_with_callbacks
    result = self._execute_task(context, task_orig)
  File "/home/airflow/.local/lib/python3.7/site-packages/airflow/models/taskinstance.py", line 1679, in _execute_task
    result = execute_callable(context=context)
  File "/home/airflow/.local/lib/python3.7/site-packages/airflow/operators/bash.py", line 195, in execute
    f'Bash command failed. The command returned a non-zero exit code {result.exit_code}.'
airflow.exceptions.AirflowException: Bash command failed. The command returned a non-zero exit code 1.

During handling of the above exception, another exception occurred:

Traceback (most recent call last):
  File "/home/airflow/.local/lib/python3.7/site-packages/airflow/models/taskinstance.py", line 2346, in email_alert
    send_email(task.email, subject, html_content)
  File "/home/airflow/.local/lib/python3.7/site-packages/airflow/utils/email.py", line 71, in send_email
    **kwargs,
  File "/home/airflow/.local/lib/python3.7/site-packages/airflow/utils/email.py", line 119, in send_email_smtp
    send_mime_email(e_from=mail_from, e_to=recipients, mime_msg=msg, conn_id=conn_id, dryrun=dryrun)
  File "/home/airflow/.local/lib/python3.7/site-packages/airflow/utils/email.py", line 230, in send_mime_email
    smtp_conn = _get_smtp_connection(smtp_host, smtp_port, smtp_timeout, smtp_ssl)
  File "/home/airflow/.local/lib/python3.7/site-packages/airflow/utils/email.py", line 264, in _get_smtp_connection
    else smtplib.SMTP(host=host, port=port, timeout=timeout)
  File "/usr/local/lib/python3.7/smtplib.py", line 251, in __init__
    (code, msg) = self.connect(host, port)
  File "/usr/local/lib/python3.7/smtplib.py", line 336, in connect
    self.sock = self._get_socket(host, port, self.timeout)
  File "/usr/local/lib/python3.7/smtplib.py", line 307, in _get_socket
    self.source_address)
  File "/usr/local/lib/python3.7/socket.py", line 728, in create_connection
    raise err
  File "/usr/local/lib/python3.7/socket.py", line 716, in create_connection
    sock.connect(sa)
OSError: [Errno 99] Cannot assign requested address

During handling of the above exception, another exception occurred:

Traceback (most recent call last):
  File "/home/airflow/.local/lib/python3.7/site-packages/airflow/models/taskinstance.py", line 1962, in handle_failure
    self.email_alert(error, task)
  File "/home/airflow/.local/lib/python3.7/site-packages/airflow/models/taskinstance.py", line 2348, in email_alert
    send_email(task.email, subject, html_content_err)
  File "/home/airflow/.local/lib/python3.7/site-packages/airflow/utils/email.py", line 71, in send_email
    **kwargs,
  File "/home/airflow/.local/lib/python3.7/site-packages/airflow/utils/email.py", line 119, in send_email_smtp
    send_mime_email(e_from=mail_from, e_to=recipients, mime_msg=msg, conn_id=conn_id, dryrun=dryrun)
  File "/home/airflow/.local/lib/python3.7/site-packages/airflow/utils/email.py", line 230, in send_mime_email
    smtp_conn = _get_smtp_connection(smtp_host, smtp_port, smtp_timeout, smtp_ssl)
  File "/home/airflow/.local/lib/python3.7/site-packages/airflow/utils/email.py", line 264, in _get_smtp_connection
    else smtplib.SMTP(host=host, port=port, timeout=timeout)
  File "/usr/local/lib/python3.7/smtplib.py", line 251, in __init__
    (code, msg) = self.connect(host, port)
  File "/usr/local/lib/python3.7/smtplib.py", line 336, in connect
    self.sock = self._get_socket(host, port, self.timeout)
  File "/usr/local/lib/python3.7/smtplib.py", line 307, in _get_socket
    self.source_address)
  File "/usr/local/lib/python3.7/socket.py", line 728, in create_connection
    raise err
  File "/usr/local/lib/python3.7/socket.py", line 716, in create_connection
    sock.connect(sa)
OSError: [Errno 99] Cannot assign requested address
[2024-04-20 09:07:29,536] {standard_task_runner.py:97} ERROR - Failed to execute job 15 for task extract_data_from_tsv (Bash command failed. The command returned a non-zero exit code 1.; 6951)
[2024-04-20 09:07:29,588] {local_task_job.py:156} INFO - Task exited with return code 1
[2024-04-20 09:07:29,832] {local_task_job.py:273} INFO - 0 downstream tasks scheduled from follow-on schedule check
